---
title: "\"Catch\" kann nicht außerhalb einer Try-Anweisung verwendet werden"
ms.date: 07/20/2015
f1_keywords:
- bc30380
- vbc30380
helpviewer_keywords:
- BC30380
ms.assetid: 73ce950d-881f-4532-8024-40a4930abd32
ms.openlocfilehash: b5097910fa669c320e2e1b57d8d090b5d66f0956
ms.sourcegitcommit: bf5c5850654187705bc94cc40ebfb62fe346ab02
ms.translationtype: MT
ms.contentlocale: de-DE
ms.lasthandoff: 09/23/2020
ms.locfileid: "91074523"
---
# <a name="catch-cannot-appear-outside-a-try-statement"></a>"Catch" kann nicht außerhalb einer Try-Anweisung verwendet werden

`Catch` muss innerhalb eines `Try...Catch...Finally` -Anweisungsblocks angezeigt werden. Entweder ist die `Catch` -Anweisung im `Try` -Block unnötig, oder die `Catch` -Anweisung befindet sich außerhalb des entsprechenden `Try` -Blocks.  
  
 **Fehler-ID:** BC30380  
  
## <a name="to-correct-this-error"></a>So beheben Sie diesen Fehler  
  
1. Löschen Sie die `Catch` -Anweisung, wenn sie unnötig ist, oder platzieren Sie sie in einem `Try...Catch...Finally` -Anweisungsblock.  
  
## <a name="see-also"></a>Siehe auch

- [Try... Catch... Abschließend-Anweisung](../language-reference/statements/try-catch-finally-statement.md)
