---
title: Die Throw-Anweisung kann außerhalb einer Catch-Anweisung oder innerhalb einer Finally-Anweisung den Operanden nicht auslassen.
ms.date: 07/20/2015
f1_keywords:
- vbc30666
- bc30666
helpviewer_keywords:
- BC30666
ms.assetid: a208a6ea-0e36-4bf1-8984-4de1a0e38a2a
ms.openlocfilehash: 05fc14b0f493b3901fda9fbdba7e0fcebae6bea5
ms.sourcegitcommit: bf5c5850654187705bc94cc40ebfb62fe346ab02
ms.translationtype: MT
ms.contentlocale: de-DE
ms.lasthandoff: 09/23/2020
ms.locfileid: "91068894"
---
# <a name="throw-statement-cannot-omit-operand-outside-a-catch-statement-or-inside-a-finally-statement"></a>Die Throw-Anweisung kann außerhalb einer Catch-Anweisung oder innerhalb einer Finally-Anweisung den Operanden nicht auslassen.

`Throw` -Anweisungen außerhalb einer `Catch` -Anweisung müssen den Namen eines Ausnahmeobjekts angeben.  
  
 **Fehler-ID:** BC30666  
  
## <a name="to-correct-this-error"></a>So beheben Sie diesen Fehler  
  
1. Geben Sie den Namen eines von `System.Exception`abgeleiteten Ausnahmeobjekts an.  
  
2. Strukturieren Sie den Code neu, damit sich die `Throw` -Anweisung innerhalb eines `Catch` -Blocks befindet.  
  
## <a name="see-also"></a>Siehe auch

- [Throw-Anweisung](../language-reference/statements/throw-statement.md)
- [Try...Catch...Finally-Anweisung](../language-reference/statements/try-catch-finally-statement.md)
- <xref:System.Exception?displayProperty=nameWithType>
- [Behandeln und Auslösen von Ausnahmen in .NET](../../standard/exceptions/index.md)
